<?xml version="1.0" encoding="utf-8"?>
<!-- This URDF was automatically created by SolidWorks to URDF Exporter! Originally created by Stephen Brawner (brawner@gmail.com) 
     Commit Version: 1.6.0-4-g7f85cfe  Build Version: 1.6.7995.38578
     For more information, please see http://wiki.ros.org/sw_urdf_exporter -->
<robot
  name="arm5">
  <link
    name="base_link">
    <inertial>
      <origin
        xyz="0.062898 -0.00043392 -0.47448"
        rpy="0 0 0" />
      <mass
        value="6.5373" />
      <inertia
        ixx="0.39748"
        ixy="-7.2205E-05"
        ixz="6.8903E-07"
        iyy="0.39743"
        iyz="-5.6522E-08"
        izz="0.012143" />
    </inertial>
    <visual>
      <origin
        xyz="0 0 0"
        rpy="0 0 0" />
      <geometry>
        <mesh
          filename="package://ti5_description/meshes/arm5/base_link.STL" />
      </geometry>
      <material
        name="">
        <color
          rgba="0.75294 0.75294 0.75294 1" />
      </material>
    </visual>
    <collision>
      <origin
        xyz="0 0 0"
        rpy="0 0 0" />
      <geometry>
        <mesh
          filename="package://ti5_description/meshes/arm5/base_link.STL" />
      </geometry>
    </collision>
  </link>
  <link
    name="Empty_Link1">
    <inertial>
      <origin
        xyz="-0.0012122 0.030854 0.019049"
        rpy="0 0 0" />
      <mass
        value="0.060372" />
      <inertia
        ixx="8.5818E-05"
        ixy="7.8725E-07"
        ixz="1.004E-06"
        iyy="6.5812E-05"
        iyz="-2.5554E-05"
        izz="5.3416E-05" />
    </inertial>
    <visual>
      <origin
        xyz="0 0 0"
        rpy="0 0 0" />
      <geometry>
        <mesh
          filename="package://ti5_description/meshes/arm5/Empty_Link1.STL" />
      </geometry>
      <material
        name="">
        <color
          rgba="0.75294 0.75294 0.75294 1" />
      </material>
    </visual>
    <collision>
      <origin
        xyz="0 0 0"
        rpy="0 0 0" />
      <geometry>
        <mesh
          filename="package://ti5_description/meshes/arm5/Empty_Link1.STL" />
      </geometry>
    </collision>
  </link>
  <joint
    name="j1"
    type="revolute">
    <origin
      xyz="-0.1255 0 0"
      rpy="-1.5708 1.5315 1.5708" />
    <parent
      link="base_link" />
    <child
      link="Empty_Link1" />
    <axis
      xyz="0 0 1" />
    <limit
      lower="-2.618"
      upper="2.618"
      effort="0"
      velocity="0" />
  </joint>
  <link
    name="Empty_Link2">
    <inertial>
      <origin
        xyz="-0.0029293 -3.0228E-05 0.0011432"
        rpy="0 0 0" />
      <mass
        value="0.36978" />
      <inertia
        ixx="0.00035458"
        ixy="7.1526E-08"
        ixz="-1.5567E-05"
        iyy="0.00034741"
        iyz="-2.7045E-07"
        izz="0.00026498" />
    </inertial>
    <visual>
      <origin
        xyz="0 0 0"
        rpy="0 0 0" />
      <geometry>
        <mesh
          filename="package://ti5_description/meshes/arm5/Empty_Link2.STL" />
      </geometry>
      <material
        name="">
        <color
          rgba="0.75294 0.75294 0.75294 1" />
      </material>
    </visual>
    <collision>
      <origin
        xyz="0 0 0"
        rpy="0 0 0" />
      <geometry>
        <mesh
          filename="package://ti5_description/meshes/arm5/Empty_Link2.STL" />
      </geometry>
    </collision>
  </link>
  <joint
    name="j2"
    type="revolute">
    <origin
      xyz="0 0 0.055"
      rpy="1.6101 1.5708 0" />
    <parent
      link="Empty_Link1" />
    <child
      link="Empty_Link2" />
    <axis
      xyz="0 0 1" />
    <limit
      lower="-1.5708"
      upper="1.5708"
      effort="0"
      velocity="0" />
  </joint>
  <link
    name="Empty_Link3">
    <inertial>
      <origin
        xyz="-0.00043966 -0.00095526 0.10658"
        rpy="0 0 0" />
      <mass
        value="0.16255" />
      <inertia
        ixx="0.00016703"
        ixy="5.3544E-07"
        ixz="1.9755E-06"
        iyy="0.00017357"
        iyz="3.5135E-06"
        izz="0.00011735" />
    </inertial>
    <visual>
      <origin
        xyz="0 0 0"
        rpy="0 0 0" />
      <geometry>
        <mesh
          filename="package://ti5_description/meshes/arm5/Empty_Link3.STL" />
      </geometry>
      <material
        name="">
        <color
          rgba="0.75294 0.75294 0.75294 1" />
      </material>
    </visual>
    <collision>
      <origin
        xyz="0 0 0"
        rpy="0 0 0" />
      <geometry>
        <mesh
          filename="package://ti5_description/meshes/arm5/Empty_Link3.STL" />
      </geometry>
    </collision>
  </link>
  <joint
    name="j3"
    type="revolute">
    <origin
      xyz="-0.0551 0 0"
      rpy="-1.5708 -0.03927 1.5708" />
    <parent
      link="Empty_Link2" />
    <child
      link="Empty_Link3" />
    <axis
      xyz="0 0 1" />
    <limit
      lower="-2.618"
      upper="2.618"
      effort="0"
      velocity="0" />
  </joint>
  <link
    name="Empty_Link4">
    <inertial>
      <origin
        xyz="-0.067652 -1.0837E-08 -0.0093648"
        rpy="0 0 0" />
      <mass
        value="0.10047" />
      <inertia
        ixx="6.2345E-05"
        ixy="-9.057E-12"
        ixz="1.0284E-05"
        iyy="7.1688E-05"
        iyz="-6.7461E-10"
        izz="6.7798E-05" />
    </inertial>
    <visual>
      <origin
        xyz="0 0 0"
        rpy="0 0 0" />
      <geometry>
        <mesh
          filename="package://ti5_description/meshes/arm5/Empty_Link4.STL" />
      </geometry>
      <material
        name="">
        <color
          rgba="0.75294 0.75294 0.75294 1" />
      </material>
    </visual>
    <collision>
      <origin
        xyz="0 0 0"
        rpy="0 0 0" />
      <geometry>
        <mesh
          filename="package://ti5_description/meshes/arm5/Empty_Link4.STL" />
      </geometry>
    </collision>
  </link>
  <joint
    name="j4"
    type="revolute">
    <origin
      xyz="0 0 0.215"
      rpy="1.6101 1.5708 0" />
    <parent
      link="Empty_Link3" />
    <child
      link="Empty_Link4" />
    <axis
      xyz="0 0 -1" />
    <limit
      lower="-2.2689"
      upper="2.2689"
      effort="0"
      velocity="0" />
  </joint>
  <link
    name="Empty_Link5">
    <inertial>
      <origin
        xyz="0.024744 -0.00024516 0.020694"
        rpy="0 0 0" />
      <mass
        value="0.038021" />
      <inertia
        ixx="3.2735E-05"
        ixy="3.8535E-08"
        ixz="-1.0284E-05"
        iyy="3.6624E-05"
        iyz="1.0189E-07"
        izz="1.6783E-05" />
    </inertial>
    <visual>
      <origin
        xyz="0 0 0"
        rpy="0 0 0" />
      <geometry>
        <mesh
          filename="package://ti5_description/meshes/arm5/Empty_Link5.STL" />
      </geometry>
      <material
        name="">
        <color
          rgba="1 1 1 1" />
      </material>
    </visual>
    <collision>
      <origin
        xyz="0 0 0"
        rpy="0 0 0" />
      <geometry>
        <mesh
          filename="package://ti5_description/meshes/arm5/Empty_Link5.STL" />
      </geometry>
    </collision>
  </link>
  <joint
    name="j5"
    type="revolute">
    <origin
      xyz="-0.152 0 0"
      rpy="1.5708 0 -1.5708" />
    <parent
      link="Empty_Link4" />
    <child
      link="Empty_Link5" />
    <axis
      xyz="0 0 1" />
    <limit
      lower="-1.5708"
      upper="1.5708"
      effort="0"
      velocity="0" />
  </joint>
</robot>
